Workbook
Name _Hlk134610415: '051523'!$B$63
Name OLE_LINK11: '051523'!$E$130
Name OLE_LINK13: '051523'!$E$11
Name OLE_LINK3: Restatement!$C$47
Name OLE_LINK4: Restatement!$C$105
Name OLE_LINK5: Restatement!$C$110
Name OLE_LINK6: Restatement!$C$114
Name OLE_LINK7: Restatement!$C$118
Name OLE_LINK8: Restatement!$C$119
Name OLE_LINK9: '051523'!$D$130

Sheet SFPo
A1: CITY OF MANILA
A2: STATEMENT OF FINANCIAL POSITION
A3: As at December 31, 2022
B4: (All amounts in Philippine Peso)
A5: (With Corresponding Figures for Calendar Year 2021 Restated)
C7: Note | D7: 2022 | E7: 2021
A8: ASSETS
B9: Current Assets
B10: Cash and Cash Equivalents | C10: 4 | D10: 8.3257302e+09 | E10: 1.0852325e+10
B11: Investments | C11: 5 | D11: 1.4290787e+09 | E11: 1.4239144e+09
B12: Receivables | C12: 6 | D12: 1.9859357e+10 | E12: 1.7723236e+10
B13: Inventories | C13: 7 | D13: 1.3274763e+09 | E13: 7.0284111e+08
B14: Prepayments and Deferred Charges | C14: 8 | D14: 2.1091234e+09 | E14: 1.3759763e+09
B15: Total Current Assets | D15: =SUM(D10:D14) -> 3.3050765e+10 | E15: =SUM(E10:E14) -> 3.2078293e+10
B17: Non-Current Assets
B18: Investment Property | C18: 9 | D18: 2.4891204e+08 | E18: 2.4891204e+08
B19: Property, Plant and Equipment | C19: 10 | D19: 4.0103501e+10 | E19: 3.3947131e+10
B20: Intagible Assets | C20: 11 | D20: 291223332 | E20: 131574000
B21: Total Non-Current Assets | D21: 4.0643636e+10 | E21: 3.4327617e+10
A23: Total Assets | D23: =+D15+D21 -> 7.3694401e+10 | E23: =+E15+E21 -> 6.640591e+10
A25: LIABILITIES
B26: Current Liabilities
B27: Financial Liabilities | C27: 12 | D27: 5.7381456e+09 | E27: 7.91375e+09
B28: Inter-Agency Payables | C28: 13 | D28: 2.1842135e+09 | E28: 1.8059449e+09
B29: Trust Liabilities | C29: 14 | D29: 1.5955701e+09 | E29: 1.1690675e+09
B30: Total Current Liabilities | D30: =SUM(D27:D29) -> 9.5179292e+09 | E30: =SUM(E27:E29) -> 1.0888762e+10
B32: Non-Current Liabilities
B33: Financial Liabilities - Non-Current | C33: 12 | D33: 1.0164062e+10 | E33: 3.7586468e+09
B34: Deferred Credits/Unearned Income | C34: 15 | D34: 6.0260209e+09 | E34: 5.1561987e+09
B35: Other Payables | C35: 16 | D35: 1.0571176e+09 | E35: 2.1570161e+09
B36: Total Non-Current Liabilities | D36: =SUM(D33:D35) -> 1.72472e+10 | E36: =SUM(E33:E35) -> 1.1071862e+10
A38: Total Liabilities | D38: =+D30+D36 -> 2.676513e+10 | E38: =+E30+E36 -> 2.1960624e+10
A40: NET ASSETS/EQUITY
A41: Government Equity | D41: 4.6929272e+10 | E41: 4.4445286e+10
A43: Total Liabilities and Net Assets/Equity | D43: =+D38+D41 -> 7.3694401e+10 | E43: =+E38+E41 -> 6.640591e+10
A44: See Accompanying Notes to Financial Statements
D45: 0 | E45: 0

Sheet SFPe
A1: CITY OF MANILA
A2: STATEMENT OF FINANCIAL PERFORMANCE
A3: For the Year Ended December 31, 2022
A4: (All amounts in Philippine Peso)
A5: (With Corresponding Figures for Calendar Year 2021 Restated)
C7: Note | D7: 2022 | E7: 2021
A8: Revenue
B9: Tax Revenue | C9: 17 | D9: 1.3046463e+10 | E9: 2.0348276e+10
B10: Share from Internal Revenue Collections | C10: 18 | D10: 4602952487 | E10: 3763196569
B11: Service and Business Income | C11: 19 | D11: 1.6374761e+09 | E11: 1.2781028e+09
B12: Shares, Grants and Donations | C12: 20 | D12: 2.174426e+08 | E12: 3.3047251e+08
B13: Gain on Sale of Assets | C13: 21 | D13: 4921062.9 | E13: 1.4011577e+09
B14: Miscellaneous Income | C14: 22 | D14: 1.8229745e+08 | E14: 16714676
A15: Total | D15: =SUM(D9:D14) -> 1.9691552e+10 | E15: =SUM(E9:E14) -> 2.713792e+10
A17: Less:
B18: Personnel Services | C18: 23 | D18: 5.1751915e+09 | E18: 5.128845e+09
B19: Maintenance and Other Operating | C19: 24 | D19: 9.2315704e+09 | E19: 1.5753609e+10
B20: Expenses
B21: Financial Expenses | C21: 25 | D21: 1.8093101e+08 | E21: 7571877.6
B22: Non-Cash Expenses | C22: 26 | D22: 1.459648e+09 | E22: 1.2950091e+09
A23: Current Operating Expenses | D23: =SUM(D18:D22) -> 1.6047341e+10 | E23: 2.2185035e+10
A25: Surplus (Deficit) From Current Operations | D25: =D15-D23 -> 3.6442113e+09 | E25: =E15-E23 -> 4.9528852e+09
B26: Add (Deduct):
B27: Transfers, Assistance and Subsidy From | C27: 27 | D27: 28178905 | E27: 0
B28: Transfers, Assistance and Subsidy To | C28: 28 | D28: -1.1884048e+09 | E28: -5.8094787e+08
A29: Surplus(Deficit) for the Period | D29: =SUM(D25:D28) -> 2.4839854e+09 | E29: =(SUM(E25:E28)) -> 4.3719373e+09
A30: See Accompanying Notes to Financial Statements

Sheet SCNAE
A1: CITY OF MANILA
A2: STATEMENT OF CHANGES IN NET ASSETS/EQUITY
A3: For the Year Ended December 31, 2022
A4: (All amounts in Philippine Peso)
A5: (With Corresponding Figures for Calendar Year 2021 Restated)
C7: Note | D7: 2022 | E7: 2021
A8: Balance at January 1 | D8: 4.4445286e+10 | E8: 4.0073349e+10
A9: Add (Deduct): Prior Period Errors | D9: 0 | E9: 0
A10: Restated Balance | D10: =+D8+D9 -> 4.4445286e+10 | E10: =+E8+E9 -> 4.0073349e+10
A11: Add: Changes in net assets/equity
A12: Adjustment of net revenue recognized | D12: 0 | E12: 0
B13: directly in net assets/equity
A14: Surplus for the period | D14: 2.4839854e+09 | E14: 4.3719373e+09
A15: Balance at December 31 | D15: =SUM(D10:D14) -> 4.6929272e+10 | E15: =SUM(E10:E14) -> 4.4445286e+10
A16: See Accompanying Notes to Financial Statements

Sheet SCF
A1: CITY OF MANILA
A2: STATEMENT OF CASH FLOWS
A3: For the Year Ended December 31, 2022
A4: (All amounts in Philippine Peso)
A5: (With Corresponding Figures for Calendar Year 2021 Restated)
C7: Note | D7: 2022 | E7: 2021
A8: Cash Flows from Operating Activities
A9: Cash Inflows
B10: Collection from taxpayers | D10: 5.5846954e+09 | E10: 1.0290853e+10
B11: Share from Internal Revenue Allotment | D11: 4602952487 | E11: 3763196569
B12: Receipts from business/service income | D12: 1.6047438e+09 | E12: 1.6726024e+09
B13: Interest Income | D13: 32732264 | E13: 47029823
B14: Other Receipts | D14: 9.6777686e+09 | E14: 5.4583141e+09
B15: Total Cash Inflows | D15: =SUM(D10:D14) -> 2.1502893e+10 | E15: =SUM(E10:E14) -> 2.1231996e+10
A16: Cash Outflows
B17: Payments to suppliers and creditors | D17: 1.2733373e+10 | E17: 1.9769266e+10
B18: Payments to employees | D18: 3.6551273e+09 | E18: 5.1504473e+09
B19: Interest Expense | D19: 1.8093101e+08 | E19: 7316427.6
B20: Other Expenses | D20: 3.3398977e+09 | E20: 1.2448507e+09
B21: Total Cash Outflows | D21: =SUM(D17:D20) -> 1.9909329e+10 | E21: =SUM(E17:E20) -> 2.617188e+10
A22: Net Cash Flows from Operating Activities | C22: 29 | D22: =+D15-D21 -> 1.5935641e+09 | E22: =+E15-E21 -> -4.9398845e+09
A23: Cash Flows from Investing Activities
A24: Cash Inflows
B25: Proceeds from Sale/Disposal of | D25: 4921063.9 | E25: 1.2573274e+09
B26: Property, Plant and Equipment
B27: Total Cash Inflows | D27: =+D25 -> 4921063.9 | E27: =+E25 -> 1.2573274e+09
A28: Cash Outflows
B29: Purchase/Construction of Property, Plant | D29: 9.2200025e+09 | E29: 4.7499103e+09
B30: and Equipment
B31: Total Cash Outflows | D31: =+D29 -> 9.2200025e+09 | E31: =+E29 -> 4.7499103e+09
A32: Net Cash Flows from Investing Activities | D32: =+D27-D31 -> -9.2150815e+09 | E32: =+E27-E31 -> -3.492583e+09
A33: Cash Flows from Financing Activities
A34: Cash Inflows
B35: Proceeds from Loans | D35: 5.0949225e+09 | E35: 2.9916851e+09
B36: Total Cash Inflows | D36: =+D35 -> 5.0949225e+09 | E36: =+E35 -> 2.9916851e+09
A37: Cash Outflows
B38: Payment of loan amortization | D38: 0 | E38: 0
B39: Total Cash Outflows | D39: 0 | E39: 0
A40: Net Cash Flows from Financing Activities | D40: =+D36+D39 -> 5.0949225e+09 | E40: =+E36+E39 -> 2.9916851e+09
A41: Total Cash Provided by (Used in) | D41: =+D22+D32+D40 -> -2.5265948e+09 | E41: =+E22+E32+E40 -> -5.4407824e+09
...

Sheet SCBAA
A1: CITY OF MANILA
A2: STATEMENT OF COMPARISON OF BUDGET AND ACTUAL AMOUNTS
A3: (All amounts in Philippine Peso)
A4: For the Year Ended December 31, 2022
A6: Particulars | G6: Budgeted Amounts | I6: Difference Original and Final Budget | J6: Actual Amounts | K6: Difference Final Budget and Actual
G7: Original | H7: Final
A8: Revenue
A9: A. | C9: Local Sources
C10: 1. | D10: Tax Revenue
E11: a. | F11: Tax Revenue - Property | G11: 6060000000 | H11: 6060000000 | I11: =G11-H11 -> 0 | J11: 5.3136702e+09 | K11: =H11-J11 -> 7.4632985e+08
E12: b. | F12: Tax Revenue - Goods and Services | G12: 4920000000 | H12: 4920000000 | I12: =G12-H12 -> 0 | J12: 4.0075911e+09 | K12: =H12-J12 -> 9.1240888e+08
E13: c. | F13: Other Local Taxes | G13: 642250000 | H13: 642250000 | I13: =G13-H13 -> 0 | J13: 3.1136158e+08 | K13: =H13-J13 -> 3.3088842e+08
D14: Total Tax Revenue | G14: =SUM(G11:G13) -> 11622250000 | H14: =SUM(H11:H13) -> 11622250000 | I14: =SUM(I11:I13) -> 0 | J14: =SUM(J11:J13) -> 9.6326229e+09 | K14: =SUM(K11:K13) -> 1.9896271e+09
C15: 2. | D15: Non-Tax Revenue
E16: a. Permit and Licence Fee
E17: b. Other Fees
E18: c. Service Income | G18: 1181613818 | H18: 1181613818 | I18: =G18-H18 -> 0 | J18: 7.7464665e+08 | K18: =H18-J18 -> 4.0696717e+08
E19: d. Business Income | G19: 707135638 | H19: 707135638 | I19: =G19-H19 -> 0 | J19: 7.7911989e+08 | K19: =H19-J19 -> -71984249
E20: e. Other Income and Receipts | G20: 1938242 | H20: 7866285 | I20: =G20-H20 -> -5928043 | J20: 1.5639209e+08 | K20: =H20-J20 -> -1.485258e+08
D21: Total Non-Tax Revenue | G21: =SUM(G18:G20) -> 1890687698 | H21: =SUM(H18:H20) -> 1896615741 | I21: =SUM(I18:I20) -> -5928043 | J21: =SUM(J18:J20) -> 1.7101586e+09 | K21: =SUM(K18:K20) -> 1.8645712e+08
A22: B. | C22: External Sources
C23: 1. | D23: Share from the National Internal Revenue Taxes (IRA) | G23: 4978610487 | H23: 4978610487 | I23: =G23-H23 -> 0 | J23: 4602952487 | K23: =H23-J23 -> 375658000
D24: a. | E24: Sale of Capital Assets | G24: 6119555749 | H24: 6119555749 | I24: =G24-H24 -> 0 | J24: 0 | K24: =H24-J24 -> 6119555749
D25: b. | E25: Proceeds from Collections of Loan Receivables | G25: 28896066 | H25: 28896066 | I25: =G25-H25 -> 0 | J25: 0 | K25: =H25-J25 -> 28896066
A26: C. | C26: Receipts from Borrowings | G26: 0 | H26: 2800000000 | I26: =G26-H26 -> -2800000000 | J26: 5.0949225e+09 | K26: =H26-J26 -> -2.2949225e+09
A27: D. | C27: Reversion of Appropriations | G27: ='[1]SCBAA-GF'!$G$31+'[1]SCBAA-SEF'!$G$29 -> 116546510 | H27: ='[1]SCBAA-GF'!$H$31+'[1]SCBAA-SEF'!$H$29 -> 598736510 | I27: =G27-H27 -> -482190000 | J27: ='[1]SCBAA-GF'!$J$31+'[1]SCBAA-SEF'!$J$29 -> 0 | K27: =H27-J27 -> 598736510
A28: Total Revenues and Receipts | G28: =SUM(G23:G27)+G21+G14 -> 24756546510 | H28: =SUM(H23:H27)+H21+H14 -> 28044664553 | I28: =SUM(I23:I27)+I21+I14 -> -3288118043 | J28: =SUM(J23:J27)+J21+J14 -> 2.1040656e+10 | K28: =SUM(K23:K27)+K21+K14 -> 7.0040081e+09
A30: Expenditures
A31: Current Appropriations
B32: General Public Services
D33: Personnel Services | G33: 1608326005 | H33: 1603517138 | I33: =G33-H33 -> 4808867 | J33: 1.3755241e+09 | K33: =H33-J33 -> 2.2799307e+08
D34: Maintenance and Other Operating Expenses | G34: 1549189443 | H34: 1701728943 | I34: =G34-H34 -> -152539500 | J34: 1.6718423e+09 | K34: =H34-J34 -> 29886653
D35: Capital Outlay | G35: 173865822 | H35: 173865822 | I35: =G35-H35 -> 0 | J35: 189356243 | K35: =H35-J35 -> -15490421
B36: Social Services and Social Welfare
D37: Personnel Services | G37: 3524124866 | H37: 3566624990 | I37: =G37-H37 -> -42500124 | J37: 3.2592552e+09 | K37: =H37-J37 -> 3.0736977e+08
D38: Maintenance and Other Operating Expenses | G38: 9323564980 | H38: 8869099214 | I38: =G38-H38 -> 454465766 | J38: 7.961134e+09 | K38: =H38-J38 -> 9.0796519e+08
D39: Capital Outlay | G39: 1665653499 | H39: 4530153499 | I39: =G39-H39 -> -2864500000 | J39: 2.2904659e+09 | K39: =H39-J39 -> 2.2396876e+09
B40: Economic Services
D41: Personnel Services | G41: 660034550 | H41: 660034550 | I41: =G41-H41 -> 0 | J41: 5.4041221e+08 | K41: =H41-J41 -> 1.1962234e+08
D42: Maintenance and Other Operating Expenses | G42: 933327074 | H42: 904474774 | I42: =G42-H42 -> 28852300 | J42: 8.8784303e+08 | K42: =H42-J42 -> 16631748
...

Sheet NFS
B1: Accounts | C1: 2022 | D1: 2021 | F1: V.1.b Increase/Decrease | G1: Percentage | H1: With Reason? | J1: V.2 Restatement (P) | K1: Should be Restatement | M1: AFR Amount 2022 | N1: AFR Amount 2021 (R)
A3: Note 4 – Cash and Cash Equivalents
B4: Accounts | C4: 2022 | D4: 2021
B5: Cash on Hand
A6: AFR check | B6: Cash Local Treasury | C6: 74452994 | D6: 24328889 | F6: =+C6-D6 -> 50124106 | G6: =+F6/D6 -> 2.0602711 | H6: No | J6: 24328889 | K6: =+D6-J6 -> 0
A7: AFR check | B7: Petty Cash | C7: 6763846 | D7: 6738184.6 | F7: =+C7-D7 -> 25661.45 | G7: =+F7/D7 -> 0.0038083626 | J7: 6738184.6 | K7: =+D7-J7 -> 0
B8: Cash in Bank | K8: =+D8-J8 -> 0
A9: AFR check | B9: Cash in Bank – Local Currency, Current Account | C9: 7.211522e+09 | D9: 7.7894579e+09 | F9: =+C9-D9 -> -5.779359e+08 | G9: =+F9/D9 -> -0.074194624 | J9: 7.8020468e+09 | K9: =+D9-J9 -> -12588967
A10: AFR check | B10: Cash in Bank - Foreign Currency, Savings Account | C10: 257912.2 | D10: 257912.2 | F10: =+C10-D10 -> 0 | G10: =+F10/D10 -> 0 | H10: Yes | J10: 257912.2 | K10: =+D10-J10 -> 0
B11: Investments in Time Deposits | K11: =+D11-J11 -> 0
A12: AFR check | B12: Cash in Bank - Local Currency, Time Deposits | C12: 1.0327335e+09 | D12: 3.0315422e+09 | F12: =+C12-D12 -> -1.9988087e+09 | G12: =+F12/D12 -> -0.65933725 | H12: Yes | J12: 3.0315422e+09 | K12: =+D12-J12 -> 0
A13: AFR check | B13: Total | C13: 8.3257302e+09 | D13: 1.0852325e+10 | J13: 1.0864914e+10 | K13: =+D13-J13 -> -12588967
B14: V.8 Mathematical Accuracy | C14: =SUM(C6:C12) -> 8.3257302e+09 | D14: =SUM(D6:D12) -> 1.0852325e+10
B15: V.8 Mathematical Accuracy | C15: =+C13-C14 -> 0 | D15: =+D13-D14 -> 0
B16: AFR check | C16: 8.3257302e+09 | D16: 1.0852325e+10
B17: AFR check | C17: =+C13-C16 -> 0 | D17: =+D13-D16 -> 0
B18: Bank | C18: 2022 | D18: 2021
B19: Landbank of the Philippines | C19: 1.6890826e+08 | D19: 1.6991947e+08
B20: Total | C20: 1.6890826e+08 | D20: 1.6991947e+08
B21: V.8 Mathematical Accuracy | C21: =+C19-C20 -> 0 | D21: =+D19-D20 -> 0
B22: Banks | C22: 2022 | D22: 2021
B23: Development Bank of the Philippines | C23: 47602334 | D23: 1.7953787e+09
B24: Landbank of the Philippines | C24: 9.8513117e+08 | D24: 1.0203122e+09
B25: Philippine National Bank | C25: - | D25: 1.0813516e+08
B26: Overseas Filipino Bank | C26: - | D26: 1.0771624e+08
B27: Total | C27: 1.0327335e+09 | D27: 3.0315422e+09
B28: V.8 Mathematical Accuracy | C28: =SUM(C23:C26) -> 1.0327335e+09 | D28: =SUM(D23:D26) -> 3.0315422e+09
B29: V.8 Mathematical Accuracy | C29: =+C27-C28 -> 0 | D29: =+D27-D28 -> 0
A31: Note 5 – Investments
B32: Accounts | C32: 2022 | D32: 2021
A33: AFR check | B33: Financial Assets Held for Trading | C33: 446250 | D33: 446250 | F33: =+C33-D33 -> 0 | G33: =+F33/D33 -> 0 | J33: 446250 | K33: =+D33-J33 -> 0
A34: AFR check | B34: Guaranty Deposits | C34: 24564565 | D34: 19400358 | F34: =+C34-D34 -> 5164207 | G34: =+F34/D34 -> 0.26619132 | J34: 19400358 | K34: =+D34-J34 -> 0
A35: AFR check | B35: Investments in Joint Venture | C35: 1.4040678e+09 | D35: 1.4040678e+09 | F35: =+C35-D35 -> 0 | G35: =+F35/D35 -> 0 | J35: 1.4040678e+09 | K35: =+D35-J35 -> 0
B36: Total | C36: 1.4290787e+09 | D36: 1.4239144e+09 | J36: 1.4239144e+09 | K36: =+D36-J36 -> 0
B37: V.8 Mathematical Accuracy | C37: =SUM(C33:C35) -> 1.4290787e+09 | D37: =SUM(D33:D35) -> 1.4239144e+09
B38: V.8 Mathematical Accuracy | C38: =+C36-C37 -> 0 | D38: =+D36-D37 -> 0
B39: AFR check | C39: 1.4290787e+09 | D39: 1.4239144e+09
B40: AFR check | C40: =+C36-C39 -> 0 | D40: =+D36-D39 -> 0
B41: Project | C41: Amount
B42: Sta. Ana Market | C42: 73790400
...

Sheet PPE
C1: CY 2022
A2: Particulars | B2: Carrying Value Dec. 31, 2021 | C2: Acquisition Cost | D2: From Other Asset | E2: Disposal | F2: Transfer/ Adjustments | G2: Depreciation Expense | H2: Carrying Value Dec. 31, 2022 | J2: Check | K2: Notes | L2: Check
A3: Land | B3: 3.5781934e+09 | C3: 33032185 | D3: 0 | E3: 0 | F3: 0 | G3: 0 | H3: 3.6112256e+09 | I3: =+B3+C3+D3-E3+F3-G3 -> 3.6112256e+09 | J3: =+H3-I3 -> 0 | K3: =+NFS!C208 -> 3.6112256e+09 | L3: =+H3-K3 -> 0
A4: Land Improvements | K4: =+NFS!C209 -> 0 | L4: =+H4-K4 -> 0
A5: Other Land Improvements | B5: 61263731 | C5: 0 | D5: 0 | E5: 0 | F5: 40433.54 | G5: 2504105.5 | H5: 58800059 | I5: =+B5+C5+D5-E5+F5-G5 -> 58800059 | J5: =+H5-I5 -> 0 | K5: =+NFS!C210 -> 58800059 | L5: =+H5-K5 -> 0
A6: Infrastructure Assets | K6: =+NFS!C211 -> 0 | L6: =+H6-K6 -> 0
A7: Road Networks | B7: 2.1960516e+09 | C7: 0 | D7: 19927404 | E7: 0 | F7: 54003862 | G7: 0 | H7: 2.2699829e+09 | I7: =+B7+C7+D7-E7+F7-G7 -> 2.2699829e+09 | J7: =+H7-I7 -> 0 | K7: =+NFS!C212 -> 2.2699829e+09 | L7: =+H7-K7 -> 0
A8: Parks, Plazas and Monuments | B8: 7.2298671e+08 | C8: 0 | E8: 0 | F8: 3.6245923e+08 | G8: 0 | H8: 1.0854459e+09 | I8: =+B8+C8+D8-E8+F8-G8 -> 1.0854459e+09 | J8: =+H8-I8 -> 0 | K8: =+NFS!C214 -> 1.0854459e+09 | L8: =+H8-K8 -> 0
A9: Other Infrastructure Assets | B9: 1.550805e+09 | C9: 0 | D9: 1.0522531e+08 | E9: 0 | F9: 7.4838952e+08 | G9: 0 | H9: 2.4044199e+09 | I9: =+B9+C9+D9-E9+F9-G9 -> 2.4044199e+09 | J9: =+H9-I9 -> 0 | K9: =+NFS!C215 -> 2.4044199e+09 | L9: =+H9-K9 -> 0
A10: Buildings and Other Structures | K10: =+NFS!C216 -> 0 | L10: =+H10-K10 -> 0
A11: Buildings | B11: 1.4963679e+09 | C11: 98359002 | D11: 55202420 | E11: 0 | F11: 90202191 | G11: 84904876 | H11: 1.6552267e+09 | I11: =+B11+C11+D11-E11+F11-G11 -> 1.6552267e+09 | J11: =+H11-I11 -> 0 | K11: =+NFS!C217 -> 1.6552267e+09 | L11: =+H11-K11 -> 0
A12: School Buildings | B12: 1.1945131e+10 | C12: 1.3705446e+08 | D12: 1.993766e+08 | E12: 0 | F12: -7.2307357e+08 | G12: 4.6319414e+08 | H12: 1.1095295e+10 | I12: =+B12+C12+D12-E12+F12-G12 -> 1.1095295e+10 | J12: =+H12-I12 -> 0 | K12: =+NFS!C218 -> 1.1095295e+10 | L12: =+H12-K12 -> 0
A13: Hospitals and Health Centers | B13: 1.1802266e+09 | C13: 1.1502119e+08 | D13: 85054413 | E13: 0 | F13: 2.2291043e+09 | G13: 94965927 | H13: 3.5144405e+09 | I13: =+B13+C13+D13-E13+F13-G13 -> 3.5144405e+09 | J13: =+H13-I13 -> 0 | K13: =+NFS!C219 -> 3.5144405e+09 | L13: =+H13-K13 -> 0
A14: Markets | B14: 3.4578156e+08 | C14: 0 | D14: 0 | E14: 0 | F14: -123368.92 | G14: 18089743 | H14: 3.2756845e+08 | I14: =+B14+C14+D14-E14+F14-G14 -> 3.2756845e+08 | J14: =+H14-I14 -> 0 | K14: =+NFS!C220 -> 3.2756845e+08 | L14: =+H14-K14 -> 0
A15: Slaughterhouses | B15: 5439104.9 | C15: 0 | D15: 0 | E15: 0 | F15: -0.01 | G15: 612386.12 | H15: 4826718.8 | I15: =+B15+C15+D15-E15+F15-G15 -> 4826718.8 | J15: =+H15-I15 -> 0 | K15: =+NFS!C221 -> 4826718.8 | L15: =+H15-K15 -> 0
A16: Other Structures | B16: 1.2295518e+09 | C16: 0 | D16: 0 | E16: 0 | F16: 3.0188252e+09 | G16: 1.1758426e+08 | H16: 4.1307927e+09 | I16: =+B16+C16+D16-E16+F16-G16 -> 4.1307927e+09 | J16: =+H16-I16 -> 0 | K16: =+NFS!C222 -> 4.1307927e+09 | L16: =+H16-K16 -> 0
A17: Machinery and Equipment | K17: =+NFS!C223 -> 0 | L17: =+H17-K17 -> 0
A18: Machinery | B18: 2831538.1 | C18: 0 | D18: 0 | E18: 0 | F18: -1680231.3 | G18: 158308 | H18: 992998.83 | I18: =+B18+C18+D18-E18+F18-G18 -> 992998.83 | J18: =+H18-I18 -> 0 | K18: =+NFS!C224 -> 992998.83 | L18: =+H18-K18 -> 0
A19: Office Equipment | B19: 1.1579825e+08 | C19: 16860788 | D19: 0 | E19: 0 | F19: -67536278 | G19: 17921452 | H19: 47201308 | I19: =+B19+C19+D19-E19+F19-G19 -> 47201308 | J19: =+H19-I19 -> 0 | K19: =+NFS!C225 -> 47201308 | L19: =+H19-K19 -> 0
A20: Information and Communication Technology Equipment | B20: 3.6795167e+08 | C20: 91097807 | D20: 0 | E20: 0 | F20: -1.1952762e+08 | G20: 80639072 | H20: 2.5888279e+08 | I20: =+B20+C20+D20-E20+F20-G20 -> 2.5888279e+08 | J20: =+H20-I20 -> 0 | K20: =+NFS!C226 -> 2.5888279e+08 | L20: =+H20-K20 -> 0
A21: Communication Equipment | B21: 36304867 | C21: 2712854.1 | D21: 0 | E21: 0 | F21: -12274266 | G21: 7810380.5 | H21: 18933075 | I21: =+B21+C21+D21-E21+F21-G21 -> 18933075 | J21: =+H21-I21 -> 0 | K21: =+NFS!C228 -> 18933075 | L21: =+H21-K21 -> 0
A22: Construction and Heavy Equipment | B22: 1.9722977e+08 | C22: 8055800 | D22: 0 | E22: 0 | F22: -148105.5 | G22: 26952977 | H22: 1.7818449e+08 | I22: =+B22+C22+D22-E22+F22-G22 -> 1.7818449e+08 | J22: =+H22-I22 -> 0 | K22: =+NFS!C229 -> 1.7818449e+08 | L22: =+H22-K22 -> 0
A23: Disaster Response and Rescue Equipment | B23: 5.0729603e+08 | C23: 31800000 | D23: 0 | E23: 0 | F23: -4316447.4 | G23: 1.0218335e+08 | H23: 4.3259624e+08 | I23: =+B23+C23+D23-E23+F23-G23 -> 4.3259624e+08 | J23: =+H23-I23 -> 0 | K23: =+NFS!C231 -> 4.3259624e+08 | L23: =+H23-K23 -> 0
A24: Military, Police and Security Equipment | B24: 5230139.6 | C24: 0 | D24: 0 | E24: 0 | F24: -5230139.6 | G24: 0 | H24: 0 | I24: =+B24+C24+D24-E24+F24-G24 -> 0 | J24: =+H24-I24 -> 0 | K24: =+NFS!C232 -> 0 | L24: =+H24-K24 -> 0
A25: Medical Equipment | B25: 1.2211379e+09 | C25: 1.0613543e+09 | D25: 0 | E25: 0 | F25: 67944393 | G25: 2.2229306e+08 | H25: 2.1281435e+09 | I25: =+B25+C25+D25-E25+F25-G25 -> 2.1281435e+09 | J25: =+H25-I25 -> 0 | K25: =+NFS!C235 -> 2.1281435e+09 | L25: =+H25-K25 -> 0
A26: Technical and Scientific Equipment | B26: 37447959 | C26: 31295333 | D26: 0 | E26: 0 | F26: -28542051 | G26: 2935546 | H26: 37265695 | I26: =+B26+C26+D26-E26+F26-G26 -> 37265695 | J26: =+H26-I26 -> 0 | K26: =+NFS!C236 -> 37265695 | L26: =+H26-K26 -> 0
A27: Other Machinery and Equipment | B27: 3.7987229e+08 | C27: 63309699 | D27: 0 | E27: 0 | F27: -2.2122654e+08 | G27: 48094542 | H27: 1.7386091e+08 | I27: =+B27+C27+D27-E27+F27-G27 -> 1.7386091e+08 | J27: =+H27-I27 -> 0 | K27: =+NFS!C238 -> 1.7386091e+08 | L27: =+H27-K27 -> 0
A28: Transportation Equipment | I28: =+B28+C28+D28-E28+F28-G28 -> 0 | J28: =+H28-I28 -> 0 | K28: =+NFS!C239 -> 0 | L28: =+H28-K28 -> 0
A29: Motor Vehicles | B29: 3.9803195e+08 | C29: 48408494 | D29: 0 | E29: 0 | F29: 16999254 | G29: 1.0148617e+08 | H29: 3.6195353e+08 | I29: =+B29+C29+D29-E29+F29-G29 -> 3.6195353e+08 | J29: =+H29-I29 -> 0 | K29: =+NFS!C240 -> 3.6195353e+08 | L29: =+H29-K29 -> 0
A30: Watercrafts | B30: 15811.96 | C30: 0 | D30: 0 | E30: 0 | F30: -15811.96 | G30: 0 | H30: 0 | I30: =+B30+C30+D30-E30+F30-G30 -> 0 | J30: =+H30-I30 -> 0 | K30: =+NFS!C241 -> 0 | L30: =+H30-K30 -> 0
A31: Furniture, Fixtures and Books | I31: =+B31+C31+D31-E31+F31-G31 -> 0 | J31: =+H31-I31 -> 0 | K31: =+NFS!C242 -> 0 | L31: =+H31-K31 -> 0
A32: Furniture and Fixtures | B32: 13764124 | C32: 33041698 | D32: 0 | E32: 0 | F32: -12159206 | G32: 3728871.4 | H32: 30917744 | I32: =+B32+C32+D32-E32+F32-G32 -> 30917744 | J32: =+H32-I32 -> 0 | K32: =+NFS!C243 -> 30917744 | L32: =+H32-K32 -> 0
A33: Books | B33: 1050326.3 | C33: 0 | D33: 0 | E33: 0 | F33: -548577.23 | G33: 59070.05 | H33: 442679.05 | I33: =+B33+C33+D33-E33+F33-G33 -> 442679.05 | J33: =+H33-I33 -> 0 | K33: =+NFS!C244 -> 442679.05 | L33: =+H33-K33 -> 0
A34: Construction in Progress (CIP) | K34: =+NFS!C245 -> 0 | L34: =+H34-K34 -> 0
A35: CIP – Infrastructure Assets | B35: 2.2338699e+09 | C35: 6.7332285e+08 | D35: -1.0591638e+08 | E35: 0 | F35: -2.7515329e+09 | G35: 0 | H35: 49743518 | I35: =+B35+C35+D35-E35+F35-G35 -> 49743518 | J35: =+H35-I35 -> 1.937151e-07 | K35: =+NFS!C246 -> 49743518 | L35: =+H35-K35 -> 0
A36: CIP – Buildings and Other Structures | B36: 3.9859651e+09 | C36: 4.0868939e+09 | D36: -3.5886977e+08 | E36: 0 | F36: -1.7484159e+09 | G36: 0 | H36: 5.9655733e+09 | I36: =+B36+C36+D36-E36+F36-G36 -> 5.9655733e+09 | J36: =+H36-I36 -> 0 | K36: =+NFS!C247 -> 5.9655733e+09 | L36: =+H36-K36 -> 0
A37: Other Property, Plant and Equipment | K37: =+NFS!C248 -> 0 | L37: =+H37-K37 -> 0
A38: Work/Zoo Animals | B38: 17950000 | C38: 40130000 | D38: 0 | E38: 0 | F38: -33106000 | G38: 0 | H38: 24974000 | I38: =+B38+C38+D38-E38+F38-G38 -> 24974000 | J38: =+H38-I38 -> 0 | K38: =+NFS!C249 -> 24974000 | L38: =+H38-K38 -> 0
A39: Other Property, Plant and Equipment | B39: 1.1358496e+08 | C39: 23835926 | D39: 0 | E39: 0 | F39: 1.6191983e+08 | G39: 63529775 | H39: 2.3581094e+08 | I39: =+B39+C39+D39-E39+F39-G39 -> 2.3581094e+08 | J39: =+H39-I39 -> 0 | K39: =+NFS!C250 -> 2.3581094e+08 | L39: =+H39-K39 -> 0
A40: Total | B40: 3.3947131e+10 | C40: 6.5955863e+09 | D40: 0 | E40: 0 | F40: 1.0204311e+09 | G40: 1.459648e+09 | H40: 4.0103501e+10 | I40: =+B40+C40+D40-E40+F40-G40 -> 4.0103501e+10 | J40: =+H40-I40 -> 0 | K40: =+NFS!C251 -> 4.0103501e+10 | L40: =+H40-K40 -> 0
...

Sheet Recon_BAA-FP
B1: Income | C1: Personal Services | D1: MOOE | E1: Financial Expenses | F1: Capital Outlay
A2: Statement of Comparison of Budget and Actual | B2: 2.1040656e+10 | C2: 5.1751915e+09 | D2: 1.1854232e+10 | E2: 3.3378215e+08 | F2: 3.1429213e+09
A3: Basis Differences:
A4: Income not considered budgetary items | B4: - | C4: - | D4: - | E4: - | F4: -
A5: Non-cash items | B5: - | C5: - | D5: - | E5: - | F5: -
A6: Gain on Sale of Assets | B6: -4921063.9 | C6: - | D6: - | E6: - | F6: -
A7: Actual Difference | B7: -1.4270471e+09 | C7: - | D7: - | E7: - | F7: -
A8: Receipts not considered as income:
A9: Sale of Capital Asset | B9: - | C9: - | D9: - | E9: - | F9: -
A10: Non-cash expenses: | B10: - | C10: - | D10: - | E10: - | F10: -
A11: Depreciation | B11: - | C11: - | D11: 1.459648e+09 | E11: - | F11: -
A12: Capital Expenditures | B12: - | C12: - | D12: - | E12: -1.5285114e+08 | F12: -
A13: Timing Difference | B13: - | C13: - | D13: - | E13: - | F13: -3.1429213e+09
A14: Unconsumed Inventories charged to current appropriations | B14: - | C14: - | D14: -2.0257894e+09 | E14: - | F14: -
A15: Actual Difference | B15: - | C15: - | D15: -2.1393845e+09 | E15: - | F15: -
A16: Per Statement of Financial Performance | B16: 1.9608688e+10 | C16: 5.1751915e+09 | D16: 9.1487065e+09 | E16: 1.8093101e+08 | F16: 0
A18: V.8 Mathematical Accuracy | B18: =SUM(B2:B15) -> 1.9608688e+10 | C18: =SUM(C2:C15) -> 5.1751915e+09 | D18: =SUM(D2:D15) -> 9.1487065e+09 | E18: =SUM(E2:E15) -> 1.8093101e+08 | F18: =SUM(F2:F15) -> 0
A19: V.8 Mathematical Accuracy | B19: =+B16-B18 -> 0 | C19: =+C16-C18 -> 0 | D19: =+D16-D18 -> 0 | E19: =+E16-E18 -> 0 | F19: =+F16-F18 -> 0
A21: check | B21: =+B2-B22 -> 0 | C21: =+C2-C22 -> 0 | D21: =+D2-D22 -> 0 | E21: =+E2-E22 -> 0 | F21: =+F2-F22 -> 0
A22: Tie-up | B22: =+SCBAA!J28 -> 2.1040656e+10 | C22: =SUM(SCBAA!J33,SCBAA!J37,SCBAA!J41,SCBAA!J58) -> 5.1751915e+09 | D22: =SUM(SCBAA!J34,SCBAA!J38,SCBAA!J42,SCBAA!J59,SCBAA!J55,SCBAA!J52,SCBAA!J49) -> 1.1854232e+10 | E22: =SUM(SCBAA!J46,SCBAA!J47) -> 3.3378215e+08 | F22: =SUM(SCBAA!J35,SCBAA!J39,SCBAA!J43,SCBAA!J50,SCBAA!J53,SCBAA!J56,SCBAA!J60) -> 3.1429213e+09
B23: =-+SFPe!D13 -> -4921062.9 | D23: =+SFPe!D22 -> 1.459648e+09
B24: =+B7 -> -1.4270471e+09 | D24: =+-SFPo!D13 -> -1.3274763e+09 | E24: =+E12 -> -1.5285114e+08
D25: =+D15 -> -2.1393845e+09
A26: sum | B26: =SUM(B22:B25) -> 1.9608688e+10 | C26: =SUM(C22:C25) -> 5.1751915e+09 | D26: =SUM(D22:D25) -> 9.8470196e+09 | E26: =SUM(E22:E25) -> 1.8093101e+08 | F26: =-SUM(F22:F25) -> -3.1429213e+09
A27: Tie-up | B27: =+SFPe!D15 -> 1.9691552e+10 | C27: =+SFPe!D18 -> 5.1751915e+09 | D27: =+SFPe!D19 -> 9.2315704e+09 | E27: =+SFPe!D21 -> 1.8093101e+08
A28: check | B28: =+B16-B27 -> -82863873 | C28: =+C16-C27 -> 0 | D28: =+D16-D27 -> -82863873 | E28: =+E16-E27 -> 0 | F28: =+F16-F27 -> 0

Sheet Restatement
A1: Accounts | B1: Previously Reported | C1: Adjustments | D1: Restated | F1: V.2 Restatement (P) | G1: Adjustments N31 | H1: Sum | I1: 2021 | J1: Difference
A3: ASSETS
A4: Cash Local Treasury | B4: 24328889 | C4: 0 | D4: 24328889 | F4: =+NFS!J6 -> 24328889 | G4: =+C4 -> 0 | H4: =+F4+G4 -> 24328889 | I4: =+NFS!D6 -> 24328889 | J4: =+H4-I4 -> 0 | K4: =+B4-F4 -> 0 | L4: =+D4-I4 -> 0
A5: Petty Cash | B5: 6738184.6 | C5: 0 | D5: 6738184.6 | F5: =+NFS!J7 -> 6738184.6 | G5: =+C5 -> 0 | H5: =+F5+G5 -> 6738184.6 | I5: =+NFS!D7 -> 6738184.6 | J5: =+H5-I5 -> 0 | K5: =+B5-F5 -> 0 | L5: =+D5-I5 -> 0
A6: Cash in Bank - Local Currency, Current Account | B6: 7.8020468e+09 | C6: -12588967 | D6: 7.7894579e+09 | F6: =+NFS!J9 -> 7.8020468e+09 | G6: =+C6 -> -12588967 | H6: =+F6+G6 -> 7.7894579e+09 | I6: =+NFS!D9 -> 7.7894579e+09 | J6: =+H6-I6 -> 0 | K6: =+B6-F6 -> 0 | L6: =+D6-I6 -> 0
A7: Cash in Bank - Foreign Currency, Savings Account | B7: 257912.2 | C7: 0 | D7: 257912.2 | F7: =+NFS!J10 -> 257912.2 | G7: =+C7 -> 0 | H7: =+F7+G7 -> 257912.2 | I7: =+NFS!D10 -> 257912.2 | J7: =+H7-I7 -> 0 | K7: =+B7-F7 -> 0 | L7: =+D7-I7 -> 0
A8: Cash in Bank -Local Currency, Time Deposits | B8: 3.0315422e+09 | C8: 0 | D8: 3.0315422e+09 | F8: =+NFS!J12 -> 3.0315422e+09 | G8: =+C8 -> 0 | H8: =+F8+G8 -> 3.0315422e+09 | I8: =+NFS!D12 -> 3.0315422e+09 | J8: =+H8-I8 -> 0 | K8: =+B8-F8 -> 0 | L8: =+D8-I8 -> 0
A9: Total Cash | B9: 1.0864914e+10 | C9: -12588967 | D9: 1.0852325e+10
A10: Financial Assets Held for Trading | B10: 446250 | C10: 0 | D10: 446250 | F10: =NFS!J33 -> 446250 | G10: =+C10 -> 0 | H10: =+F10+G10 -> 446250 | I10: =NFS!D33 -> 446250 | J10: =+H10-I10 -> 0 | K10: =+B10-F10 -> 0 | L10: =+D10-I10 -> 0
A11: Guaranty Deposits | B11: 19400358 | C11: 0 | D11: 19400358 | F11: =NFS!J34 -> 19400358 | G11: =+C11 -> 0 | H11: =+F11+G11 -> 19400358 | I11: =NFS!D34 -> 19400358 | J11: =+H11-I11 -> 0 | K11: =+B11-F11 -> 0 | L11: =+D11-I11 -> 0
A12: Investment in Joint Ventures | B12: 1.4040678e+09 | C12: 0 | D12: 1.4040678e+09 | F12: =NFS!J35 -> 1.4040678e+09 | G12: =+C12 -> 0 | H12: =+F12+G12 -> 1.4040678e+09 | I12: =NFS!D35 -> 1.4040678e+09 | J12: =+H12-I12 -> 0 | K12: =+B12-F12 -> 0 | L12: =+D12-I12 -> 0
A13: Total Investment | B13: 1.4239144e+09 | C13: 0 | D13: 1.4239144e+09
A14: Accounts Receivable | B14: 3.2227719e+08 | C14: 0 | D14: 3.2227719e+08 | F14: =NFS!J57 -> 3.2227719e+08 | G14: =+C14 -> 0 | H14: =+F14+G14 -> 3.2227719e+08 | I14: =NFS!D57 -> 3.2227719e+08 | J14: =+H14-I14 -> 0 | K14: =+B14-F14 -> 0 | L14: =+D14-I14 -> 0
A15: Real Property Tax Receivable | B15: 7.0240616e+09 | C15: 1.8348835e+09 | D15: 8.8589451e+09 | F15: =NFS!J58 -> 7.0240616e+09 | G15: =+C15 -> 1.8348835e+09 | H15: =+F15+G15 -> 8.8589451e+09 | I15: =NFS!D58 -> 8.8589451e+09 | J15: =+H15-I15 -> 0 | K15: =+B15-F15 -> 0 | L15: =+D15-I15 -> 0
A16: Special Education Tax Receivable | B16: 3.5148686e+09 | C16: 2.2687947e+09 | D16: 5.7836633e+09 | F16: =NFS!J59 -> 3.5148686e+09 | G16: =+C16 -> 2.2687947e+09 | H16: =+F16+G16 -> 5.7836633e+09 | I16: =NFS!D59 -> 5.7836633e+09 | J16: =+H16-I16 -> 0 | K16: =+B16-F16 -> 0 | L16: =+D16-I16 -> 0
A17: Loans Receivable - Others | B17: 2.0017853e+08 | C17: 0 | D17: 2.0017853e+08 | F17: =NFS!J60 -> 2.0017853e+08 | G17: =+C17 -> 0 | H17: =+F17+G17 -> 2.0017853e+08 | I17: =NFS!D60 -> 2.0017853e+08 | J17: =+H17-I17 -> 0 | K17: =+B17-F17 -> 0 | L17: =+D17-I17 -> 0
A18: Operating Lease Receivable | B18: 77410239 | C18: 0 | D18: 77410239 | F18: =NFS!J63 -> 77410239 | G18: =+C18 -> 0 | H18: =+F18+G18 -> 77410239 | I18: =NFS!D63 -> 77410239 | J18: =+H18-I18 -> 0 | K18: =+B18-F18 -> 0 | L18: =+D18-I18 -> 0
A19: Due from National Government Agencies | B19: 3.2353118e+08 | C19: 0 | D19: 3.2353118e+08 | F19: =NFS!J66 -> 3.2353118e+08 | G19: =+C19 -> 0 | H19: =+F19+G19 -> 3.2353118e+08 | I19: =NFS!D66 -> 3.2353118e+08 | J19: =+H19-I19 -> 0 | K19: =+B19-F19 -> 0 | L19: =+D19-I19 -> 0
A20: Due from Government-Owned and/or Controlled Corporations | B20: 1.6119638e+08 | C20: -1.50065e+08 | D20: 11131383 | F20: =NFS!J67 -> 1.6119638e+08 | G20: =+C20 -> -1.50065e+08 | H20: =+F20+G20 -> 11131383 | I20: =NFS!D67 -> 11131383 | J20: =+H20-I20 -> 0 | K20: =+B20-F20 -> 0 | L20: =+D20-I20 -> 0
A21: Due from Local Government Units | B21: 77717365 | C21: 0 | D21: 77717365 | F21: =NFS!J68 -> 77717365 | G21: =+C21 -> 0 | H21: =+F21+G21 -> 77717365 | I21: =NFS!D68 -> 77717365 | J21: =+H21-I21 -> 0 | K21: =+B21-F21 -> 0 | L21: =+D21-I21 -> 0
A22: Due from Joint Venture | B22: 60484469 | C22: 0 | D22: 60484469 | F22: =NFS!J69 -> 60484469 | G22: =+C22 -> 0 | H22: =+F22+G22 -> 60484469 | I22: =NFS!D69 -> 60484469 | J22: =+H22-I22 -> 0 | K22: =+B22-F22 -> 0 | L22: =+D22-I22 -> 0
A23: Advances for Payroll | B23: 8623335.1 | C23: 0 | D23: 8623335.1 | F23: =NFS!J72 -> 8623335.1 | G23: =+C23 -> 0 | H23: =+F23+G23 -> 8623335.1 | I23: =NFS!D72 -> 8623335.1 | J23: =+H23-I23 -> 0 | K23: =+B23-F23 -> 0 | L23: =+D23-I23 -> 0
A24: Advances to Special Disbursing Officer | B24: 1.8498229e+08 | C24: -79296303 | D24: 1.0568599e+08 | F24: =NFS!J73 -> 1.8498229e+08 | G24: =+C24 -> -79296303 | H24: =+F24+G24 -> 1.0568599e+08 | I24: =NFS!D73 -> 1.0568599e+08 | J24: =+H24-I24 -> 0 | K24: =+B24-F24 -> 0 | L24: =+D24-I24 -> 0
A25: Advances for Officers and Employees | B25: 3119326 | C25: 0 | D25: 3119326 | F25: =NFS!J74 -> 3119326 | G25: =+C25 -> 0 | H25: =+F25+G25 -> 3119326 | I25: =NFS!D74 -> 3119326 | J25: =+H25-I25 -> 0 | K25: =+B25-F25 -> 0 | L25: =+D25-I25 -> 0
A26: Receivables - Disallowances/Charges | B26: 1972954.2 | C26: 0 | D26: 1972954.2 | F26: =NFS!J77 -> 1972954.2 | G26: =+C26 -> 0 | H26: =+F26+G26 -> 1972954.2 | I26: =NFS!D77 -> 1972954.2 | J26: =+H26-I26 -> 0 | K26: =+B26-F26 -> 0 | L26: =+D26-I26 -> 0
A27: Due from Officers and Employees | B27: 17743.56 | C27: 1274263.8 | D27: 1292007.4 | F27: =NFS!J78 -> 17743.56 | G27: =+C27 -> 1274263.8 | H27: =+F27+G27 -> 1292007.4 | I27: =NFS!D78 -> 1292007.4 | J27: =+H27-I27 -> 0 | K27: =+B27-F27 -> 0 | L27: =+D27-I27 -> 0
A28: Other Receivables | B28: 1.8871675e+09 | C28: 36226.96 | D28: 1.8872037e+09 | F28: =NFS!J79 -> 1.8871675e+09 | G28: =+C28 -> 36226.96 | H28: =+F28+G28 -> 1.8872037e+09 | I28: =NFS!D79 -> 1.8872037e+09 | J28: =+H28-I28 -> 0 | K28: =+B28-F28 -> 0 | L28: =+D28-I28 -> 0
A29: Total Receivables | B29: 1.3847609e+10 | C29: 3.8756274e+09 | D29: 1.7723236e+10
A30: Merchandise Inventory | B30: 25699950 | C30: 0 | D30: 25699950 | F30: =NFS!J139 -> 25699950 | G30: =+C30 -> 0 | H30: =+F30+G30 -> 25699950 | I30: =NFS!D139 -> 25699950 | J30: =+H30-I30 -> 0 | K30: =+B30-F30 -> 0 | L30: =+D30-I30 -> 0
A31: Office Supplies Inventory | B31: 53159369 | C31: 0 | D31: 53159369 | F31: =NFS!J140 -> 53159369 | G31: =+C31 -> 0 | H31: =+F31+G31 -> 53159369 | I31: =NFS!D140 -> 53159369 | J31: =+H31-I31 -> 0 | K31: =+B31-F31 -> 0 | L31: =+D31-I31 -> 0
A32: Accountable Forms, Plates and Stickers | B32: 2097324 | C32: 0 | D32: 2097324 | F32: =NFS!J141 -> 2097324 | G32: =+C32 -> 0 | H32: =+F32+G32 -> 2097324 | I32: =NFS!D141 -> 2097324 | J32: =+H32-I32 -> 0 | K32: =+B32-F32 -> 0 | L32: =+D32-I32 -> 0
A33: Non-Accountable Forms Inventory | B33: 638200 | C33: 0 | D33: 638200 | F33: =NFS!J143 -> 638200 | G33: =+C33 -> 0 | H33: =+F33+G33 -> 638200 | I33: =NFS!D143 -> 638200 | J33: =+H33-I33 -> 0 | K33: =+B33-F33 -> 0 | L33: =+D33-I33 -> 0
A34: Food Supplies Inventory | B34: 16232842 | C34: 0 | D34: 16232842 | F34: =NFS!J147 -> 16232842 | G34: =+C34 -> 0 | H34: =+F34+G34 -> 16232842 | I34: =NFS!D147 -> 16232842 | J34: =+H34-I34 -> 0 | K34: =+B34-F34 -> 0 | L34: =+D34-I34 -> 0
A35: Drugs and Medicines Inventory | B35: 1.2289204e+08 | C35: 0 | D35: 1.2289204e+08 | F35: =NFS!J148 -> 1.2289204e+08 | G35: =+C35 -> 0 | H35: =+F35+G35 -> 1.2289204e+08 | I35: =NFS!D148 -> 1.2289204e+08 | J35: =+H35-I35 -> 0 | K35: =+B35-F35 -> 0 | L35: =+D35-I35 -> 0
A36: Medical, Dental and Laboratory Supplies Inventory | B36: 2.1847303e+08 | C36: 0 | D36: 2.1847303e+08 | F36: =NFS!J149 -> 2.1847303e+08 | G36: =+C36 -> 0 | H36: =+F36+G36 -> 2.1847303e+08 | I36: =NFS!D149 -> 2.1847303e+08 | J36: =+H36-I36 -> 0 | K36: =+B36-F36 -> 0 | L36: =+D36-I36 -> 0
A37: Fuel, Oil and Lubricants Inventory | B37: 7604051.6 | C37: 0 | D37: 7604051.6 | F37: =NFS!J151 -> 7604051.6 | G37: =+C37 -> 0 | H37: =+F37+G37 -> 7604051.6 | I37: =NFS!D151 -> 7604051.6 | J37: =+H37-I37 -> 0 | K37: =+B37-F37 -> 0 | L37: =+D37-I37 -> 0
A38: Textbooks and Instructional Materials Inventory | B38: 99581267 | C38: 0 | D38: 99581267 | F38: =NFS!J156 -> 99581267 | G38: =+C38 -> 0 | H38: =+F38+G38 -> 99581267 | I38: =NFS!D156 -> 99581267 | J38: =+H38-I38 -> 0 | K38: =+B38-F38 -> 0 | L38: =+D38-I38 -> 0
A39: Other Supplies and Materials Inventory | B39: 1.5646304e+08 | C39: 0 | D39: 1.5646304e+08 | F39: =NFS!J154 -> 1.5646304e+08 | G39: =+C39 -> 0 | H39: =+F39+G39 -> 1.5646304e+08 | I39: =NFS!D154 -> 1.5646304e+08 | J39: =+H39-I39 -> 0 | K39: =+B39-F39 -> 0 | L39: =+D39-I39 -> 0
A40: Total Inventories | B40: 7.0284111e+08 | C40: 0 | D40: 7.0284111e+08
A41: Advances to Contractors | B41: 1.2126966e+09 | C41: 0.48 | D41: 1.2126966e+09 | F41: =NFS!J191 -> 1.2126966e+09 | G41: =+C41 -> 0.48 | H41: =+F41+G41 -> 1.2126966e+09 | I41: =NFS!D191 -> 1.2126966e+09 | J41: =+H41-I41 -> 0 | K41: =+B41-F41 -> 0 | L41: =+D41-I41 -> 0
...

Sheet ExecSum
B1: Executive Office | C1: City Council | D1: Total | F1: Particulars | G1: 2022 | H1: 2021 | I1: Increase/ (Decrease) | K1: Tie-Up | N1: Check
A2: Elected | B2: 2 | C2: 38 | D2: 40 | F2: Assets | G2: 7.3694401e+10 | H2: 6.640591e+10 | I2: 7.288491e+09 | K2: =+[2]SFPo!D22 -> 7.3694401e+10 | L2: =+[2]SFPo!E22 -> 6.640591e+10 | M2: =+K2-L2 -> 7.288491e+09 | N2: =+G2-K2 -> 0 | O2: =+H2-L2 -> 0.00034332275 | P2: =+I2-M2 -> -0.00034141541
A3: Permanent | B3: 8562 | C3: 125 | D3: 8687 | F3: Liabilities | G3: 2.676513e+10 | H3: 2.1960624e+10 | I3: 4.8045056e+09 | K3: =+[2]SFPo!D37 -> 2.676513e+10 | L3: =+[2]SFPo!E37 -> 2.1960624e+10 | M3: =+K3-L3 -> 4.8045056e+09 | N3: =+G3-K3 -> 0 | O3: =+H3-L3 -> 0.00031661987 | P3: =+I3-M3 -> -0.00032043457
A4: Co-Terminus | B4: 35 | C4: 466 | D4: 501 | F4: Equity | G4: 4.6929272e+10 | H4: 4.4445286e+10 | I4: 2.4839854e+09 | K4: =+[2]SFPo!D40 -> 4.6929272e+10 | L4: =+[2]SFPo!E40 -> 4.4445286e+10 | M4: =+K4-L4 -> 2.4839854e+09 | N4: =+G4-K4 -> 0 | O4: =+H4-L4 -> 0 | P4: =+I4-M4 -> 0
A5: Temporary/Casual | B5: 75 | C5: 0 | D5: 75 | F5: Income | G5: 1.9691552e+10 | H5: 2.713792e+10 | I5: -7.4463678e+09 | K5: =+[2]SFPe!D14 -> 1.9691552e+10 | L5: =+[2]SFPe!E14 -> 2.713792e+10 | M5: =+K5-L5 -> -7.4463678e+09 | N5: =+G5-K5 -> 0 | O5: =+H5-L5 -> 0 | P5: =+I5-M5 -> 0
A6: Consultant | B6: 308 | C6: 9 | D6: 317 | F6: Expenses | G6: 1.6047341e+10 | H6: 2.2185035e+10 | I6: -6.1376939e+09 | K6: =+[2]SFPe!D21 -> 1.6047341e+10 | L6: =+[2]SFPe!E21 -> 2.2185035e+10 | M6: =+K6-L6 -> -6.1376939e+09 | N6: =+G6-K6 -> 0 | O6: =+H6-L6 -> 0 | P6: =+I6-M6 -> 0
A7: Contractual | B7: 0 | C7: 5 | D7: 5 | F7: Transfers, Assistance and Subsidy From | G7: 5.5420313e+08 | H7: 447200735 | I7: 1.070024e+08 | K7: =+[2]SFPe!D25 -> 28178905 | L7: =+[2]SFPe!E25 -> 0 | M7: =+K7-L7 -> 28178905 | N7: =+G7-K7 -> 5.2602422e+08 | O7: =+H7-L7 -> 447200735 | P7: =+I7-M7 -> 78823490
A8: Job Order | B8: 7044 | C8: 1195 | D8: 8239 | F8: Transfers, Assistance and Subsidy to | G8: 6.0602281e+08 | H8: 1.3374714e+08 | I8: 4.7227567e+08 | K8: =-[2]SFPe!D27-[2]SFPe!D26 -> 1.1884048e+09 | L8: =-[2]SFPe!E27-[2]SFPe!E26 -> 5.8094787e+08 | M8: =+K8-L8 -> 6.0745697e+08 | N8: =+G8-K8 -> -5.8238204e+08 | O8: =+H8-L8 -> -447200735 | P8: =+I8-M8 -> -1.351813e+08
A9: Medical Residents | B9: 140 | C9: 0 | D9: 140
A10: Other Professionals | B10: 1174 | C10: 0 | D10: 1174
A11: Total | B11: 17340 | C11: 1838 | D11: 19178 | F11: Particulars | G11: 2022 | H11: 2021 | I11: Increase/
B12: =SUM(B2:B10) -> 17340 | C12: =SUM(C2:C10) -> 1838 | D12: =SUM(D2:D10) -> 19178 | I12: (Decrease)
B13: =+B11-B12 -> 0 | C13: =+C11-C12 -> 0 | D13: =+D11-D12 -> 0 | F13: Appropriations | G13: 26040437284 | H13: 36456216237 | I13: -10415778953 | K13: =[2]SCBAA!H58 -> 2.6040437e+10 | L13: 36456216237 | M13: =+K13-L13 -> -1.0415779e+10 | N13: =+G13-K13 -> 0.44999695 | O13: =+H13-L13 -> 0 | P13: =+I13-M13 -> 0.44999695
F14: Obligations | G14: 22299910724 | H14: 20663633285 | I14: 1636277439 | K14: =+[2]SCBAA!J58 -> 2.0506127e+10 | L14: 2.0663633e+10 | M14: =+K14-L14 -> -1.5750598e+08 | N14: =+G14-K14 -> 1.7937834e+09 | O14: =+H14-L14 -> -0.15000153 | P14: =+I14-M14 -> 1.7937834e+09
B17: Amount per FS | F17: Particulars | G17: GF | H17: SEF | I17: Total | K17: Per Annex
B18: =+[2]SFPe!D8 -> 1.3046463e+10 | C18: =+I18-B18 -> 0 | F18: Tax Revenue | G18: 9.8641788e+09 | H18: 3.1822838e+09 | I18: 1.3046463e+10 | J18: =SUM(G18:H18)-I18 -> 0 | K18: =14467131250.12-K19 -> 9.8641788e+09 | L18: 3.1822838e+09 | M18: =SUM(K18:L18) -> 1.3046463e+10 | N18: =+G18-K18 -> 0 | O18: =+H18-L18 -> 0 | P18: =+I18-M18 -> 0
B19: =[2]SFPe!D9 -> 4602952487 | C19: =+I19-B19 -> 0 | F19: Share from Internal Revenue Collections | G19: 4602952487 | H19: 0 | I19: 4602952487 | J19: =SUM(G19:H19)-I19 -> 0 | K19: 4602952487 | L19: 0 | M19: =SUM(K19:L19) -> 4602952487 | N19: =+G19-K19 -> 0 | O19: =+H19-L19 -> 0 | P19: =+I19-M19 -> 0
B20: =+[2]SFPe!D10 -> 1.6374761e+09 | C20: =+I20-B20 -> 0 | F20: Service and Business Income | G20: 1.6262537e+09 | H20: 11222393 | I20: 1.6374761e+09 | J20: =SUM(G20:H20)-I20 -> 0 | K20: 1.6262537e+09 | L20: 11222393 | M20: =SUM(K20:L20) -> 1.6374761e+09 | N20: =+G20-K20 -> 0 | O20: =+H20-L20 -> 0 | P20: =+I20-M20 -> 0
B21: =+[2]SFPe!D11 -> 2.174426e+08 | C21: =+I21-B21 -> 0 | F21: Shares, Grants and Donations | G21: 2.174426e+08 | H21: 0 | I21: 2.174426e+08 | J21: =SUM(G21:H21)-I21 -> 0 | K21: 2.174426e+08 | L21: 0 | M21: =SUM(K21:L21) -> 2.174426e+08 | N21: =+G21-K21 -> 0 | O21: =+H21-L21 -> 0 | P21: =+I21-M21 -> 0
B22: =+[2]SFPe!D12 -> 4921062.9 | C22: =+I22-B22 -> 1 | F22: Gain on Sale of Assets | G22: 4921063.9 | H22: 0 | I22: 4921063.9 | J22: =SUM(G22:H22)-I22 -> 0 | K22: 4921063.9 | L22: 0 | M22: =SUM(K22:L22) -> 4921063.9 | N22: =+G22-K22 -> 0 | O22: =+H22-L22 -> 0 | P22: =+I22-M22 -> 0
B23: =+[2]SFPe!D13 -> 1.8229745e+08 | C23: =+I23-B23 -> -1.01 | F23: Miscellaneous Income | G23: 1.8229744e+08 | H23: 0 | I23: 1.8229744e+08 | J23: =SUM(G23:H23)-I23 -> 0 | K23: 1.8229744e+08 | L23: 0 | M23: =SUM(K23:L23) -> 1.8229744e+08 | N23: =+G23-K23 -> 0 | O23: =+H23-L23 -> 0 | P23: =+I23-M23 -> 0
F24: Total | G24: 1.6498046e+10 | H24: 3.1935062e+09 | I24: 1.9691552e+10 | J24: =SUM(G24:H24)-I24 -> 0
G25: =SUM(G18:G23) -> 1.6498046e+10 | H25: =SUM(H18:H23) -> 3.1935062e+09 | I25: =SUM(I18:I23) -> 1.9691552e+10
G26: =+G24-G25 -> 0 | H26: =+H24-H25 -> 0 | I26: =+I24-I25 -> 0

Sheet ExecSum-revised
B1: Executive Office | C1: City Council | D1: Total | F1: Particulars | G1: 2022 | H1: 2021 | I1: Increase/ (Decrease) | K1: Tie-Up | N1: Check
A2: Elected | B2: 2 | C2: 38 | D2: 40 | F2: Assets | G2: 7.3694401e+10 | H2: 6.640591e+10 | I2: 7.288491e+09 | K2: =+[2]SFPo!D22 -> 7.3694401e+10 | L2: =+[2]SFPo!E22 -> 6.640591e+10 | M2: =+K2-L2 -> 7.288491e+09 | N2: =+G2-K2 -> 0 | O2: =+H2-L2 -> 0.00034332275 | P2: =+I2-M2 -> -0.00034141541
A3: Permanent | B3: 8562 | C3: 125 | D3: 8687 | F3: Liabilities | G3: 2.676513e+10 | H3: 2.1960624e+10 | I3: 4.8045056e+09 | K3: =+[2]SFPo!D37 -> 2.676513e+10 | L3: =+[2]SFPo!E37 -> 2.1960624e+10 | M3: =+K3-L3 -> 4.8045056e+09 | N3: =+G3-K3 -> 0 | O3: =+H3-L3 -> 0.00031661987 | P3: =+I3-M3 -> -0.00032043457
A4: Co-Terminus | B4: 35 | C4: 466 | D4: 501 | F4: Equity | G4: 4.6929272e+10 | H4: 4.4445286e+10 | I4: 2.4839854e+09 | K4: =+[2]SFPo!D40 -> 4.6929272e+10 | L4: =+[2]SFPo!E40 -> 4.4445286e+10 | M4: =+K4-L4 -> 2.4839854e+09 | N4: =+G4-K4 -> 0 | O4: =+H4-L4 -> 0 | P4: =+I4-M4 -> 0
A5: Temporary/Casual | B5: 75 | C5: 0 | D5: 75 | F5: Income | G5: 1.9691552e+10 | H5: 2.713792e+10 | I5: -7.4463678e+09 | K5: =+[2]SFPe!D14 -> 1.9691552e+10 | L5: =+[2]SFPe!E14 -> 2.713792e+10 | M5: =+K5-L5 -> -7.4463678e+09 | N5: =+G5-K5 -> 0 | O5: =+H5-L5 -> 0 | P5: =+I5-M5 -> 0
A6: Consultant | B6: 308 | C6: 9 | D6: 317 | F6: Expenses | G6: 1.6047341e+10 | H6: 2.2185035e+10 | I6: -6.1376939e+09 | K6: =+[2]SFPe!D21 -> 1.6047341e+10 | L6: =+[2]SFPe!E21 -> 2.2185035e+10 | M6: =+K6-L6 -> -6.1376939e+09 | N6: =+G6-K6 -> 0 | O6: =+H6-L6 -> 0 | P6: =+I6-M6 -> 0
A7: Contractual | B7: 0 | C7: 5 | D7: 5 | F7: Transfers, Assistance and Subsidy From | G7: 28178905 | H7: 0 | I7: 28178905 | K7: =+[2]SFPe!D25 -> 28178905 | L7: =+[2]SFPe!E25 -> 0 | M7: =+K7-L7 -> 28178905 | N7: =+G7-K7 -> 0 | O7: =+H7-L7 -> 0 | P7: =+I7-M7 -> 0
A8: Job Order | B8: 7044 | C8: 1195 | D8: 8239 | F8: Transfers, Assistance and Subsidy to | G8: 1.1884048e+09 | H8: 5.8094787e+08 | I8: 6.0745697e+08 | K8: =-[2]SFPe!D27-[2]SFPe!D26 -> 1.1884048e+09 | L8: =-[2]SFPe!E27-[2]SFPe!E26 -> 5.8094787e+08 | M8: =+K8-L8 -> 6.0745697e+08 | N8: =+G8-K8 -> 0 | O8: =+H8-L8 -> 0 | P8: =+I8-M8 -> 0
A9: Medical Residents | B9: 140 | C9: 0 | D9: 140
A10: Other Professionals | B10: 1174 | C10: 0 | D10: 1174
A11: Total | B11: 17340 | C11: 1838 | D11: 19178 | F11: Particulars | G11: 2022 | H11: 2021 | I11: Increase/
B12: =SUM(B2:B10) -> 17340 | C12: =SUM(C2:C10) -> 1838 | D12: =SUM(D2:D10) -> 19178 | I12: (Decrease)
B13: =+B11-B12 -> 0 | C13: =+C11-C12 -> 0 | D13: =+D11-D12 -> 0 | F13: Appropriations | G13: 2.6040437e+10 | H13: 36456216237 | I13: -1.0415779e+10 | K13: =[2]SCBAA!H58 -> 2.6040437e+10 | L13: 36456216237 | M13: =+K13-L13 -> -1.0415779e+10 | N13: =+G13-K13 -> 0 | O13: =+H13-L13 -> 0 | P13: =+I13-M13 -> 0
F14: Obligations | G14: 2.0506127e+10 | H14: 2.0663633e+10 | I14: -1.5750598e+08 | K14: =+[2]SCBAA!J58 -> 2.0506127e+10 | L14: 2.0663633e+10 | M14: =+K14-L14 -> -1.5750598e+08 | N14: =+G14-K14 -> 0 | O14: =+H14-L14 -> 0 | P14: =+I14-M14 -> -3.3676624e-06
B17: Amount per FS | F17: Particulars | G17: GF | H17: SEF | I17: Total | K17: Per Annex
B18: =+[2]SFPe!D8 -> 1.3046463e+10 | C18: =+I18-B18 -> 0 | F18: Tax Revenue | G18: 9.8641788e+09 | H18: 3.1822838e+09 | I18: 1.3046463e+10 | J18: =SUM(G18:H18)-I18 -> 0 | K18: =14467131250.12-K19 -> 9.8641788e+09 | L18: 3.1822838e+09 | M18: =SUM(K18:L18) -> 1.3046463e+10 | N18: =+G18-K18 -> 0 | O18: =+H18-L18 -> 0 | P18: =+I18-M18 -> 0
B19: =[2]SFPe!D9 -> 4602952487 | C19: =+I19-B19 -> 0 | F19: Share from Internal Revenue Collections | G19: 4602952487 | H19: 0 | I19: 4602952487 | J19: =SUM(G19:H19)-I19 -> 0 | K19: 4602952487 | L19: 0 | M19: =SUM(K19:L19) -> 4602952487 | N19: =+G19-K19 -> 0 | O19: =+H19-L19 -> 0 | P19: =+I19-M19 -> 0
B20: =+[2]SFPe!D10 -> 1.6374761e+09 | C20: =+I20-B20 -> 0 | F20: Service and Business Income | G20: 1.6262537e+09 | H20: 11222393 | I20: 1.6374761e+09 | J20: =SUM(G20:H20)-I20 -> 0 | K20: 1.6262537e+09 | L20: 11222393 | M20: =SUM(K20:L20) -> 1.6374761e+09 | N20: =+G20-K20 -> 0 | O20: =+H20-L20 -> 0 | P20: =+I20-M20 -> 0
B21: =+[2]SFPe!D11 -> 2.174426e+08 | C21: =+I21-B21 -> 0 | F21: Shares, Grants and Donations | G21: 2.174426e+08 | H21: 0 | I21: 2.174426e+08 | J21: =SUM(G21:H21)-I21 -> 0 | K21: 2.174426e+08 | L21: 0 | M21: =SUM(K21:L21) -> 2.174426e+08 | N21: =+G21-K21 -> 0 | O21: =+H21-L21 -> 0 | P21: =+I21-M21 -> 0
B22: =+[2]SFPe!D12 -> 4921062.9 | C22: =+I22-B22 -> 1 | F22: Gain on Sale of Assets | G22: 4921063.9 | H22: 0 | I22: 4921063.9 | J22: =SUM(G22:H22)-I22 -> 0 | K22: 4921063.9 | L22: 0 | M22: =SUM(K22:L22) -> 4921063.9 | N22: =+G22-K22 -> 0 | O22: =+H22-L22 -> 0 | P22: =+I22-M22 -> 0
B23: =+[2]SFPe!D13 -> 1.8229745e+08 | C23: =+I23-B23 -> -1 | F23: Miscellaneous Income | G23: 1.8229744e+08 | H23: 0 | I23: 1.8229744e+08 | J23: =SUM(G23:H23)-I23 -> 0 | K23: 1.8229744e+08 | L23: 0 | M23: =SUM(K23:L23) -> 1.8229744e+08 | N23: =+G23-K23 -> 0 | O23: =+H23-L23 -> 0 | P23: =+I23-M23 -> 0
F24: Total | G24: 1.6498046e+10 | H24: 3.1935062e+09 | I24: 1.9691552e+10 | J24: =SUM(G24:H24)-I24 -> 0
G25: =SUM(G18:G23) -> 1.6498046e+10 | H25: =SUM(H18:H23) -> 3.1935062e+09 | I25: =SUM(I18:I23) -> 1.9691552e+10
G26: =+G24-G25 -> 0 | H26: =+H24-H25 -> 0 | I26: =+I24-I25 -> 0

Sheet Part2
A1: Table 1. Inventory accounts as of December 31, 2022
A2: Account Title | B2: Balance | D2: Total
B3: General Fund (GF) | C3: Special Education Fund (SEF)
A4: Merchandise Inventory | B4: 25857318 | C4: 0 | D4: 25857318 | E4: =SUM(B4:C4) -> 25857318
A5: Welfare Goods for Distribution | B5: 0 | C5: 0 | D5: 0 | E5: =SUM(B5:C5) -> 0
A6: Office Supplies Inventory | B6: 73820391 | C6: 0 | D6: 73820391 | E6: =SUM(B6:C6) -> 73820391
A7: Accountable Forms Inventory | B7: 1530567 | C7: 0 | D7: 1530567 | E7: =SUM(B7:C7) -> 1530567
A8: Non-Accountable Forms Inventory | B8: 1406700 | C8: 0 | D8: 1406700 | E8: =SUM(B8:C8) -> 1406700
A9: Animal/Zoological Supplies Inventory | B9: 5074926.4 | C9: 0 | D9: 5074926.4 | E9: =SUM(B9:C9) -> 5074926.4
A10: Food Supplies Inventory | B10: 20549093 | C10: 0 | D10: 20549093 | E10: =SUM(B10:C10) -> 20549093
A11: Drugs and Medicines Inventory | B11: 2.4962345e+08 | C11: 0 | D11: 2.4962345e+08 | E11: =SUM(B11:C11) -> 2.4962345e+08 | G11: =+D11 -> 2.4962345e+08
A12: Medical, Dental and Laboratory Supplies Inventory | B12: 3.4745792e+08 | C12: 0 | D12: 3.4745792e+08 | E12: =SUM(B12:C12) -> 3.4745792e+08 | G12: =+D12 -> 3.4745792e+08
A13: Fuel, Oil and Lubricant Inventory | B13: 41029729 | C13: 0 | D13: 41029729 | E13: =SUM(B13:C13) -> 41029729
A14: Textbooks and Instructional Materials Inventory | B14: 0 | C14: 1.6099266e+08 | D14: 1.6099266e+08 | E14: =SUM(B14:C14) -> 1.6099266e+08 | G14: =+D14 -> 1.6099266e+08
A15: Construction Materials Inventory | B15: 17552499 | C15: 0 | D15: 17552499 | E15: =SUM(B15:C15) -> 17552499
A16: Other Supplies and Materials for Distribution | B16: 0 | C16: 0 | D16: 0 | E16: =SUM(B16:C16) -> 0
A17: Other Supplies and Materials Inventory | B17: 2.4769397e+08 | C17: 1.3488709e+08 | D17: 3.8258106e+08 | E17: =SUM(B17:C17) -> 3.8258106e+08 | G17: =+D17 -> 3.8258106e+08
A18: Total Inventory | B18: 1.0315966e+09 | C18: 2.9587975e+08 | D18: 1.3274763e+09 | E18: =SUM(E4:E17) -> 1.3274763e+09 | G18: =SUM(G4:G17) -> 1.1406551e+09
A19: Total Current Assets | D19: 3.3050765e+10 | E19: =+E18-D18 -> 0 | F19: =+D19-G19 -> 0 | G19: =+[3]SFPo!D14 -> 3.3050765e+10 | H19: SFPo
A20: Per cent of Total Current Assets | D20: 4.02 | E20: =+[3]SFPo!D12 -> 1.3274763e+09 | F20: SFPo | G20: =+G18/E18 -> 0.85926587
E21: =+E18-E20 -> 0
A22: Overstatement representing inexistent inventories still carried in the inventory accounts | C22: 35521927 | D22: =C22 -> 35521927
A23: Understatement representing unrecorded inventories:
A24: Office Supplies Inventory | B24: 95800
A25: Fuel, Oil and Lubricants Inventory | B25: 477500
A26: Covid Supplies Inventory | B26: 2354000 | C26: 2927300 | D26: =SUM(B24:B26) -> 2927300
A27: Net Overstatement | C27: 32594627 | D27: =D22-D26 -> 32594627 | E27: =C27-D27 -> 0
A29: Account Title | B29: Inventory per books of accounts | C29: Inventory per physical count by end users | D29: Inexistent/ (Unrecorded)
A30: Merchandise Inventory | B30: 25857318 | C30: 0 | D30: 25857318 | E30: =+B30-C30 -> 25857318 | F30: =+D30-E30 -> 0
A31: Accountable Forms Inventory | B31: 1530567 | C31: 1530567 | D31: 0 | E31: =+B31-C31 -> 0 | F31: =+D31-E31 -> 0
A32: Non-Accountable Forms Inventory | B32: 1406700 | C32: 1406700 | D32: 0 | E32: =+B32-C32 -> 0 | F32: =+D32-E32 -> 0
A33: Animal and Zoological Supplies Inventory | B33: 5074926.4 | C33: 5074926.4 | D33: 0 | E33: =+B33-C33 -> 0 | F33: =+D33-E33 -> 0
A34: Food Supplies Inventory | B34: 20549093 | C34: 20549093 | D34: 0 | E34: =+B34-C34 -> 0 | F34: =+D34-E34 -> 0
A35: Drugs and Medicines Inventory | B35: 2.4962345e+08 | C35: 2.4962345e+08 | D35: 0 | E35: =+B35-C35 -> 0 | F35: =+D35-E35 -> 0
A36: Medical, Dental and Laboratory Supplies Inventory | B36: 3.4745792e+08 | C36: 3.4534211e+08 | D36: 2115808 | E36: =+B36-C36 -> 2115808 | F36: =+D36-E36 -> 0
A37: Textbooks and Instructional Materials Inventory | B37: 1.6099266e+08 | C37: 1.5401716e+08 | D37: 6975500 | E37: =+B37-C37 -> 6975500 | F37: =+D37-E37 -> 0
A38: Construction Materials Inventory/RM Other PPE | B38: 17552499 | C38: 17552499 | D38: 0 | E38: =+B38-C38 -> 0 | F38: =+D38-E38 -> 0
A39: Other Supplies and Materials Inventory | B39: 3.8258106e+08 | C39: 3.8200776e+08 | D39: 573300.5 | E39: =+B39-C39 -> 573300.5 | F39: =+D39-E39 -> 0
A40: Total Inexistent Inventory | D40: 35521927 | E40: =SUM(E30:E39) -> 35521927 | F40: =+D40-E40 -> 0
A41: Office Supplies Inventory | B41: 73820391 | C41: 73916191 | D41: -95800 | E41: =+B41-C41 -> -95800 | F41: =+D41-E41 -> 0
...

Sheet 051523
B2: Account | C2: Less than 1 year | D2: More than 1 year | E2: Total
B3: Due from National Government Agencies | C3: 15338433 | D3: 3.2316865e+08 | E3: 3.3850708e+08 | F3: =SUM(C3:D3) -> 3.3850708e+08
B4: Due from Government-Owned and/or Controlled Corporations | C4: 26661435 | D4: 25583087 | E4: 52244521 | F4: =SUM(C4:D4) -> 52244521
B5: Due from Local Government Units | C5: 77717365 | D5: - | E5: 77717365 | F5: =SUM(C5:D5) -> 77717365
B6: Due from Joint Venture | C6: 60484569 | D6: - | E6: 60484569 | F6: =SUM(C6:D6) -> 60484569
B8: Account | C8: Less than 1 year | D8: More than 1 year | E8: Total
B9: Advances for Payroll | C9: 8043746.6 | D9: - | E9: 8043746.6 | F9: =SUM(C9:D9) -> 8043746.6
B10: Advances for Special Disbursing Officer | C10: 26359730 | D10: 68481235 | E10: 94840966 | F10: =SUM(C10:D10) -> 94840966
B11: Advances for Officers and Employees | C11: 601840 | D11: 2603152.9 | E11: 3204992.9 | F11: =SUM(C11:D11) -> 3204992.9
B13: Account | C13: Less than 1 year | D13: More than 1 year | E13: Total
B14: Receivables - Disallowances/ Charges | C14: - | D14: 1972954.2 | E14: 1972954.2 | F14: =SUM(C14:D14) -> 1972954.2
B15: Due from Officers and Employees | C15: - | D15: 17743.56 | E15: 17743.56 | F15: =SUM(C15:D15) -> 17743.56
B16: Other Receivables | C16: 13235184 | D16: 1.2994487e+09 | E16: 1.3126839e+09 | F16: =SUM(C16:D16) -> 1.3126839e+09
B19: Redevelopment of Manila Zoo | C19: 1.3117153e+09
B20: Binondominium 1 | C20: 4.0060669e+08
B21: Tondominium 1 | C21: 4.983675e+08
B22: Tondominium 2 | C22: 4.9834893e+08
B23: Ospital ng Maynila and Parking Building | C23: 2.2909616e+09
C24: =SUM(C19:C23) -> 5000000000
A26: 1 | B26: Dr. Albert Elementary School | C26: 2000000000
A27: 2 | B27: Rosauro Almario Elementary School | C27: 1900000000
A28: 3 | B28: Manila Science High School | C28: 1300000000
A29: 4 | B29: Pedro Gil Residences | C29: 1585000000
A30: 5 | B30: San Lazaro Residences | C30: 2015000000
A31: 6 | B31: San Sebastian Residences | C31: 1200000000
C32: =SUM(C26:C31) -> 10000000000
B34: Account | C34: On Demand | D34: < 1 Year but > 3 years | E34: Total
B35: Due to BIR | C35: 2.8446955e+08 | D35: 1.4272427e+08 | E35: 427,193,827.17 | F35: =SUM(C35:D35) -> 4.2719383e+08
B36: Due to GSIS | C36: 30454472 | D36: 37467307 | E36: 67921779 | F36: =SUM(C36:D36) -> 67921779
B37: Due to Pag-IBIG | C37: 14298385 | D37: 2756349.9 | E37: 17054735 | F37: =SUM(C37:D37) -> 17054735
B38: Due to PhilHealth | C38: 7610055.7 | D38: 29312443 | E38: 36922499 | F38: =SUM(C38:D38) -> 36922499
B39: Due to NGAs | C39: 84726000 | D39: 3.9870186e+08 | E39: 4.8342786e+08 | F39: =SUM(C39:D39) -> 4.8342786e+08
B40: Due to GOCCs | C40: 1.4496137e+08 | D40: 3.0719054e+08 | E40: 4.5215191e+08 | F40: =SUM(C40:D40) -> 4.5215191e+08
B41: Due to LGUs | C41: 6611826.4 | D41: 6.9292909e+08 | E41: 6.9954092e+08 | F41: =SUM(C41:D41) -> 6.9954092e+08
B44: Accounts | C44: 2022 | D44: 2021
B45: Tax Revenue - Individual and Corporation
B46: Professional Tax | C46: 6019190 | D46: 5448488.9
B47: Community Tax | C47: 96360293 | D47: 91180305
B48: Sub-total | C48: 1.0237948e+08 | D48: 96628794 | E48: =SUM(C46:C47) -> 1.0237948e+08 | F48: =SUM(D46:D47) -> 96628794 | G48: =+C48-E48 -> 0 | H48: =+D48-F48 -> 0
B49: Tax Revenue - Property
...
